2017-07-31 05:19:48,507 - django.request - ERROR - Internal Server Error: /admin/WeChatModel/keyword/
Traceback (most recent call last):
  File "/usr/local/lib/python3.6/site-packages/django/contrib/sessions/backends/base.py", line 202, in _get_session
    return self._session_cache
AttributeError: 'SessionStore' object has no attribute '_session_cache'

During handling of the above exception, another exception occurred:

Traceback (most recent call last):
  File "/usr/local/lib/python3.6/site-packages/django/db/backends/base/base.py", line 213, in ensure_connection
    self.connect()
  File "/usr/local/lib/python3.6/site-packages/django/db/backends/base/base.py", line 189, in connect
    self.connection = self.get_new_connection(conn_params)
  File "/usr/local/lib/python3.6/site-packages/django/db/backends/mysql/base.py", line 274, in get_new_connection
    conn = Database.connect(**conn_params)
  File "/usr/local/lib/python3.6/site-packages/mysqlclient-1.3.10-py3.6-linux-x86_64.egg/MySQLdb/__init__.py", line 86, in Connect
    return Connection(*args, **kwargs)
  File "/usr/local/lib/python3.6/site-packages/mysqlclient-1.3.10-py3.6-linux-x86_64.egg/MySQLdb/connections.py", line 204, in __init__
    super(Connection, self).__init__(*args, **kwargs2)
_mysql_exceptions.OperationalError: (2005, "Unknown MySQL server host 'bjtopcom.xicp.cn' (110)")

The above exception was the direct cause of the following exception:

Traceback (most recent call last):
  File "/usr/local/lib/python3.6/site-packages/django/core/handlers/exception.py", line 41, in inner
    response = get_response(request)
  File "/usr/local/lib/python3.6/site-packages/django/core/handlers/base.py", line 249, in _legacy_get_response
    response = self._get_response(request)
  File "/usr/local/lib/python3.6/site-packages/django/core/handlers/base.py", line 187, in _get_response
    response = self.process_exception_by_middleware(e, request)
  File "/usr/local/lib/python3.6/site-packages/django/core/handlers/base.py", line 185, in _get_response
    response = wrapped_callback(request, *callback_args, **callback_kwargs)
  File "/usr/local/lib/python3.6/site-packages/django/contrib/admin/options.py", line 551, in wrapper
    return self.admin_site.admin_view(view)(*args, **kwargs)
  File "/usr/local/lib/python3.6/site-packages/django/utils/decorators.py", line 149, in _wrapped_view
    response = view_func(request, *args, **kwargs)
  File "/usr/local/lib/python3.6/site-packages/django/views/decorators/cache.py", line 57, in _wrapped_view_func
    response = view_func(request, *args, **kwargs)
  File "/usr/local/lib/python3.6/site-packages/django/contrib/admin/sites.py", line 213, in inner
    if not self.has_permission(request):
  File "/usr/local/lib/python3.6/site-packages/django/contrib/admin/sites.py", line 187, in has_permission
    return request.user.is_active and request.user.is_staff
  File "/usr/local/lib/python3.6/site-packages/django/utils/functional.py", line 238, in inner
    self._setup()
  File "/usr/local/lib/python3.6/site-packages/django/utils/functional.py", line 385, in _setup
    self._wrapped = self._setupfunc()
  File "/usr/local/lib/python3.6/site-packages/django/contrib/auth/middleware.py", line 24, in <lambda>
    request.user = SimpleLazyObject(lambda: get_user(request))
  File "/usr/local/lib/python3.6/site-packages/django/contrib/auth/middleware.py", line 12, in get_user
    request._cached_user = auth.get_user(request)
  File "/usr/local/lib/python3.6/site-packages/django/contrib/auth/__init__.py", line 210, in get_user
    user_id = _get_user_session_key(request)
  File "/usr/local/lib/python3.6/site-packages/django/contrib/auth/__init__.py", line 61, in _get_user_session_key
    return get_user_model()._meta.pk.to_python(request.session[SESSION_KEY])
  File "/usr/local/lib/python3.6/site-packages/django/contrib/sessions/backends/base.py", line 57, in __getitem__
    return self._session[key]
  File "/usr/local/lib/python3.6/site-packages/django/contrib/sessions/backends/base.py", line 207, in _get_session
    self._session_cache = self.load()
  File "/usr/local/lib/python3.6/site-packages/django/contrib/sessions/backends/db.py", line 35, in load
    expire_date__gt=timezone.now()
  File "/usr/local/lib/python3.6/site-packages/django/db/models/manager.py", line 85, in manager_method
    return getattr(self.get_queryset(), name)(*args, **kwargs)
  File "/usr/local/lib/python3.6/site-packages/django/db/models/query.py", line 374, in get
    num = len(clone)
  File "/usr/local/lib/python3.6/site-packages/django/db/models/query.py", line 232, in __len__
    self._fetch_all()
  File "/usr/local/lib/python3.6/site-packages/django/db/models/query.py", line 1118, in _fetch_all
    self._result_cache = list(self._iterable_class(self))
  File "/usr/local/lib/python3.6/site-packages/django/db/models/query.py", line 53, in __iter__
    results = compiler.execute_sql(chunked_fetch=self.chunked_fetch)
  File "/usr/local/lib/python3.6/site-packages/django/db/models/sql/compiler.py", line 863, in execute_sql
    sql, params = self.as_sql()
  File "/usr/local/lib/python3.6/site-packages/django/db/models/sql/compiler.py", line 420, in as_sql
    where, w_params = self.compile(self.where) if self.where is not None else ("", [])
  File "/usr/local/lib/python3.6/site-packages/django/db/models/sql/compiler.py", line 373, in compile
    sql, params = node.as_sql(self, self.connection)
  File "/usr/local/lib/python3.6/site-packages/django/db/models/sql/where.py", line 79, in as_sql
    sql, params = compiler.compile(child)
  File "/usr/local/lib/python3.6/site-packages/django/db/models/sql/compiler.py", line 373, in compile
    sql, params = node.as_sql(self, self.connection)
  File "/usr/local/lib/python3.6/site-packages/django/db/models/lookups.py", line 169, in as_sql
    lhs_sql, params = self.process_lhs(compiler, connection)
  File "/usr/local/lib/python3.6/site-packages/django/db/models/lookups.py", line 162, in process_lhs
    db_type = self.lhs.output_field.db_type(connection=connection)
  File "/usr/local/lib/python3.6/site-packages/django/db/models/fields/__init__.py", line 644, in db_type
    return connection.data_types[self.get_internal_type()] % data
  File "/usr/local/lib/python3.6/site-packages/django/utils/functional.py", line 35, in __get__
    res = instance.__dict__[self.name] = self.func(instance)
  File "/usr/local/lib/python3.6/site-packages/django/db/backends/mysql/base.py", line 174, in data_types
    if self.features.supports_microsecond_precision:
  File "/usr/local/lib/python3.6/site-packages/django/utils/functional.py", line 35, in __get__
    res = instance.__dict__[self.name] = self.func(instance)
  File "/usr/local/lib/python3.6/site-packages/django/db/backends/mysql/features.py", line 53, in supports_microsecond_precision
    return self.connection.mysql_version >= (5, 6, 4) and Database.version_info >= (1, 2, 5)
  File "/usr/local/lib/python3.6/site-packages/django/utils/functional.py", line 35, in __get__
    res = instance.__dict__[self.name] = self.func(instance)
  File "/usr/local/lib/python3.6/site-packages/django/db/backends/mysql/base.py", line 385, in mysql_version
    with self.temporary_connection() as cursor:
  File "/usr/local/lib/python3.6/contextlib.py", line 81, in __enter__
    return next(self.gen)
  File "/usr/local/lib/python3.6/site-packages/django/db/backends/base/base.py", line 591, in temporary_connection
    cursor = self.cursor()
  File "/usr/local/lib/python3.6/site-packages/django/db/backends/base/base.py", line 254, in cursor
    return self._cursor()
  File "/usr/local/lib/python3.6/site-packages/django/db/backends/base/base.py", line 229, in _cursor
    self.ensure_connection()
  File "/usr/local/lib/python3.6/site-packages/django/db/backends/base/base.py", line 213, in ensure_connection
    self.connect()
  File "/usr/local/lib/python3.6/site-packages/django/db/utils.py", line 94, in __exit__
    six.reraise(dj_exc_type, dj_exc_value, traceback)
  File "/usr/local/lib/python3.6/site-packages/django/utils/six.py", line 685, in reraise
    raise value.with_traceback(tb)
  File "/usr/local/lib/python3.6/site-packages/django/db/backends/base/base.py", line 213, in ensure_connection
    self.connect()
  File "/usr/local/lib/python3.6/site-packages/django/db/backends/base/base.py", line 189, in connect
    self.connection = self.get_new_connection(conn_params)
  File "/usr/local/lib/python3.6/site-packages/django/db/backends/mysql/base.py", line 274, in get_new_connection
    conn = Database.connect(**conn_params)
  File "/usr/local/lib/python3.6/site-packages/mysqlclient-1.3.10-py3.6-linux-x86_64.egg/MySQLdb/__init__.py", line 86, in Connect
    return Connection(*args, **kwargs)
  File "/usr/local/lib/python3.6/site-packages/mysqlclient-1.3.10-py3.6-linux-x86_64.egg/MySQLdb/connections.py", line 204, in __init__
    super(Connection, self).__init__(*args, **kwargs2)
django.db.utils.OperationalError: (2005, "Unknown MySQL server host 'bjtopcom.xicp.cn' (110)")
